Workbook

Sheet Raipur
B2: Costing for TMT
B4: Steel Costing | C4: RAIPUR
B5: Item | C5: Consumption | D5: Unit | E5: Rate | F5: Cost | G5: Recovery amount | H5: Effective cost | I5: Total cost
A7: 850 | B7: Pallet DRI | C7: 68 | D7: % | E7: 26650 | F7: =E7*C7/100 -> 18122 | G7: 0.8 | H7: =F7/G7 -> 22652.5 | I7: =H7 -> 22652.5
A8: 128 | B8: Pig Iron | C8: 12 | D8: % | E8: 37550 | F8: =E8*C8/100 -> 4506 | G8: 0.94 | H8: =F8/G8 -> 4793.617 | I8: =H8 -> 4793.617
A9: 104 | B9: Scrap | C9: 10 | D9: % | E9: 34800 | F9: =E9*C9/100 -> 3480 | G9: 0.96 | H9: =F9/G9 -> 3625 | I9: =H9 -> 3625
B10: Silico Manganese | C10: 14 | D10: kg | E10: 74.4 | F10: =E10*C10 -> 1041.6 | G10: 1 | H10: =F10/G10 -> 1041.6 | I10: =H10 -> 1041.6
A11: 119 | B11: Iron Ore DRI | C11: 10 | D11: % | E11: 30500 | F11: =E11*C11/100 -> 3050 | G11: 0.84 | H11: =F11/G11 -> 3630.9524 | I11: =H11 -> 3630.9524
B12: Power (incldg ancilliaries) | C12: 700 | E12: 6.5 | F12: =E12*C12 -> 4550 | I12: =E12*C12 -> 4550
B13: Stores | C13: 1 | D13: Rs/T | E13: 500 | F13: =E13*C13 -> 500 | I13: 550
B14: Manpower | C14: 1 | D14: Rs/T | E14: 550 | F14: =E14 -> 550 | I14: 500
B15: Billet Cost | C15: 46098 | I15: =SUM(I7:I14) -> 41343.669
B16: Market price of Billet | I16: 41900
B17: Nett Margin | I17: =I16-I15 -> 556.3306
B19: Rolling Mill Cost | C19: Hot charging (own billet - direct rolling )
B20: Item | C20: Consumption | D20: Unit | E20: Rate | F20: Cost
B21: Cost of Billet | F21: =I15 -> 41343.669
B22: Scale loss | C22: 0.8 | D22: % | E22: =I15 -> 41343.669 | F22: =E22*C22/100 -> 330.74936
B23: Power | C23: 120 | D23: unit | E23: 6.5 | F23: =E23*C23 -> 780
B24: Stores | C24: 1 | D24: Rs/T | E24: 400 | F24: =E24*C24 -> 400
B25: Manpower | C25: 1 | D25: Rs/T | E25: 700 | F25: =E25*C25 -> 700
B26: Fuel cost | C26: 0 | D26: scm/t | E26: 47 | F26: =E26*C26 -> 0
B27: Cutting loss | C27: 0 | D27: % | E27: =SUM(F21:F26) -> 43554.419 | F27: =E27*C27/100 -> 0
B28: Rolling cost | F28: =SUM(F22:F27) -> 2210.7494
B29: Yield loss | C29: 4.5 | D29: % | E29: =SUM(F21:F27) -> 43554.419 | F29: =E29*C29/100 -> 1959.9488
B30: Add back cost of scrap | C30: -25 | D30: kg | E30: 36 | F30: =E30*C30 -> -900
B31: Short length realiz | C31: -20 | D31: kg | E31: 43 | F31: =E31*C31 -> -860
B32: Interest + Depreciation | C32: LS | D32: Rs/T | E32: 500 | F32: 500
B33: Total cost | F33: =F28+I15+F32 -> 44054.419
B34: Market price for TMT | F34: 46200
B35: Margin for mfr | F35: =F34-F33 -> 2145.5812

Sheet NCR
A2: Costing for TMT
A4: Steel Costing | B4: NCR
A5: Item | B5: Consumption | C5: Unit | D5: Rate | E5: Cost | F5: Recovery amount | G5: Effective cost | H5: Total cost
A7: Pallet DRI | B7: 38 | C7: % | D7: =Raipur!E7+3100 -> 29750 | E7: =D7*B7/100 -> 11305 | F7: 0.79 | G7: =E7/F7 -> 14310.127 | H7: =G7 -> 14310.127
A8: Pig Iron | B8: 12 | C8: % | D8: =Raipur!E8+3100 -> 40650 | E8: =D8*B8/100 -> 4878 | F8: 0.94 | G8: =E8/F8 -> 5189.3617 | H8: =G8 -> 5189.3617
A9: Scrap | B9: 50 | C9: % | D9: =35200-500 -> 34700 | E9: =D9*B9/100 -> 17350 | F9: 0.96 | G9: =E9/F9 -> 18072.917 | H9: =G9 -> 18072.917
A10: Silico Manganese | B10: 14 | C10: kg | D10: =Raipur!E10 -> 74.4 | E10: =D10*B10 -> 1041.6 | F10: 1 | G10: =E10/F10 -> 1041.6 | H10: =G10 -> 1041.6
A11: Iron Ore DRI | B11: 0 | C11: % | D11: =Raipur!E11+3100 -> 33600 | E11: =D11*B11/100 -> 0 | F11: 0.83 | G11: =E11/F11 -> 0 | H11: =G11 -> 0
A12: Power (incldg ancilliaries) | B12: 650 | D12: 6.5 | E12: =D12*B12 -> 4225 | H12: =D12*B12 -> 4225
A13: Stores | B13: 1 | C13: LS | D13: 500 | E13: =D13*B13 -> 500 | H13: =D13*B13 -> 500
A14: Manpower | B14: 1 | C14: LS | D14: 550 | E14: =D14 -> 550 | H14: =D14*B14 -> 550
A15: Billet Cost | B15: =Raipur!B15 -> Billet Cost | C15: =Raipur!C15 -> 46098 | H15: =SUM(H7:H14) -> 43889.005
A16: Market price of Billet | B16: Market price of Billet | H16: =44400-500 -> 43900
A17: Nett Margin | B17: Nett Margin | H17: =H16-H15 -> 10.995049
A19: Rolling Mill Cost | B19: Rolling Mill Cost | C19: Hot charging (own billet - direct rolling )
A20: Item | B20: Item | C20: Consumption | D20: Unit | E20: Rate | F20: Cost
A21: Cost of Billet | B21: Cost of Billet | F21: =H15 -> 43889.005
A22: Scale loss | B22: Scale loss | C22: 0.8 | D22: % | E22: =H15 -> 43889.005 | F22: =E22*C22/100 -> 351.11204
A23: Power | B23: Power | C23: 120 | D23: unit | E23: 6.5 | F23: =E23*C23 -> 780
A24: Stores | B24: Stores | C24: 1 | D24: Rs/T | E24: 400 | F24: =E24*C24 -> 400
A25: Manpower | B25: Manpower | C25: 1 | D25: Rs/T | E25: 700 | F25: =E25*C25 -> 700
A26: Fuel cost | B26: Fuel cost | C26: 0 | D26: scm/t | E26: 47 | F26: =E26*C26 -> 0
A27: Cutting loss | B27: Cutting loss | C27: 0 | D27: % | E27: =SUM(F21:F26) -> 46120.117 | F27: =E27*C27/100 -> 0
A28: Rolling cost | B28: Rolling cost | F28: =SUM(F22:F27) -> 2231.112
A29: Yield loss | B29: Yield loss | C29: 4.5 | D29: % | E29: =SUM(F21:F27) -> 46120.117 | F29: =E29*C29/100 -> 2075.4053
A30: Add back cost of scrap | B30: Add back cost of scrap | C30: -45 | D30: kg | E30: 36 | F30: =E30*C30 -> -1620
A31: Short length realiz | B31: Short length realiz | C31: -20 | D31: kg | E31: 43 | F31: =E31*C31 -> -860
A32: Interest + Depreciation | B32: Interest + Depreciation | C32: LS | D32: Rs/T | E32: 500 | F32: 500
A33: Total cost | B33: Total cost | F33: =H15+F28+F32 -> 46620.117
A34: Market price for TMT | B34: Market price for TMT | F34: 50750
A35: Margin for mfr | B35: Margin for mfr | F35: =F34-F33 -> 4129.883

Sheet Raipur NCR (29 Oct)
B2: Costing for TMT
B4: Steel Costing | C4: RAIPUR | M4: NCR | W4: NCR Fe 550
B5: Item | C5: Consumption | D5: Unit | E5: Rate | F5: Cost | G5: Recovery amount | H5: Effective cost | I5: Total cost | J5: Change from Oct | K5: Impact (Rs PMT) | L5: Oct end | M5: Consumption | N5: Unit | O5: Rate | P5: Cost | Q5: Recovery amount | R5: Effective cost | S5: Total cost | W5: Consumption | X5: Unit | Y5: Rate | Z5: Cost | AA5: Recovery amount | AB5: Effective cost | AC5: Total cost
A7: 850 | B7: Pallet DRI | C7: 68 | D7: % | E7: 22100 | F7: =E7*C7/100 -> 15028 | G7: 0.8 | H7: =F7/G7 -> 18785 | I7: =H7 -> 18785 | J7: =E7-L7 -> 0 | L7: 22100 | M7: 38 | N7: % | O7: =E7+3100 -> 25200 | P7: =O7*M7/100 -> 9576 | Q7: 0.79 | R7: =P7/Q7 -> 12121.519 | S7: =R7 -> 12121.519 | W7: 5 | X7: % | Y7: 32000 | Z7: =Y7*W7/100 -> 1600 | AA7: 0.79 | AB7: =Z7/AA7 -> 2025.3165 | AC7: =AB7 -> 2025.3165
A8: 128 | B8: Pig Iron | C8: 12 | D8: % | E8: 31800 | F8: =E8*C8/100 -> 3816 | G8: 0.94 | H8: =F8/G8 -> 4059.5745 | I8: =H8 -> 4059.5745 | L8: 31800 | M8: 12 | N8: % | O8: =E8+3100 -> 34900 | P8: =O8*M8/100 -> 4188 | Q8: 0.94 | R8: =P8/Q8 -> 4455.3191 | S8: =R8 -> 4455.3191 | W8: 15 | X8: % | Y8: 42800 | Z8: =Y8*W8/100 -> 6420 | AA8: 0.94 | AB8: =Z8/AA8 -> 6829.7872 | AC8: =AB8 -> 6829.7872
A9: 104 | B9: Scrap | C9: 10 | D9: % | E9: 30300 | F9: =E9*C9/100 -> 3030 | G9: 0.96 | H9: =F9/G9 -> 3156.25 | I9: =H9 -> 3156.25 | L9: 30300 | M9: 50 | N9: % | O9: =29900-500 -> 29400 | P9: =O9*M9/100 -> 14700 | Q9: 0.96 | R9: =P9/Q9 -> 15312.5 | S9: =R9 -> 15312.5 | W9: 80 | X9: % | Y9: 39500 | Z9: =Y9*W9/100 -> 31600 | AA9: 0.96 | AB9: =Z9/AA9 -> 32916.667 | AC9: =AB9 -> 32916.667
B10: Silico Manganese | C10: 14 | D10: kg | E10: 71.7 | F10: =E10*C10 -> 1003.8 | G10: 1 | H10: =F10/G10 -> 1003.8 | I10: =H10 -> 1003.8 | L10: 71.7 | M10: 14 | N10: kg | O10: =E10 -> 71.7 | P10: =O10*M10 -> 1003.8 | Q10: 1 | R10: =P10/Q10 -> 1003.8 | S10: =R10 -> 1003.8 | W10: 14 | X10: kg | Y10: 69 | Z10: =Y10*W10 -> 966 | AA10: 1 | AB10: =Z10/AA10 -> 966 | AC10: =AB10 -> 966
A11: 119 | B11: Iron Ore DRI | C11: 10 | D11: % | E11: 26100 | F11: =E11*C11/100 -> 2610 | G11: 0.84 | H11: =F11/G11 -> 3107.1429 | I11: =H11 -> 3107.1429 | L11: 26100 | M11: 0 | N11: % | O11: =E11+3100 -> 29200 | P11: =O11*M11/100 -> 0 | Q11: 0.83 | R11: =P11/Q11 -> 0 | S11: =R11 -> 0 | W11: 0 | X11: % | Y11: 34700 | Z11: =Y11*W11/100 -> 0 | AA11: 0.83 | AB11: =Z11/AA11 -> 0 | AC11: =AB11 -> 0
B12: Power (incldg ancilliaries) | C12: 700 | E12: 6.5 | F12: =E12*C12 -> 4550 | I12: =E12*C12 -> 4550 | M12: 650 | O12: 6.5 | P12: =O12*M12 -> 4225 | S12: =O12*M12 -> 4225 | W12: 650 | Y12: 6.5 | Z12: =Y12*W12 -> 4225 | AC12: =Y12*W12 -> 4225
B13: Stores | C13: 1 | D13: Rs/T | E13: 500 | F13: =E13*C13 -> 500 | I13: 550 | M13: 1 | N13: LS | O13: 500 | P13: =O13*M13 -> 500 | S13: =O13*M13 -> 500 | W13: 1 | X13: LS | Y13: 500 | Z13: =Y13*W13 -> 500 | AC13: =Y13*W13 -> 500
B14: Manpower | C14: 1 | D14: Rs/T | E14: 550 | F14: =E14 -> 550 | I14: 500 | M14: 1 | N14: LS | O14: 550 | P14: =O14 -> 550 | S14: =O14*M14 -> 550 | W14: 1 | X14: LS | Y14: 550 | Z14: =Y14 -> 550 | AC14: =Y14*W14 -> 550
B15: Billet Cost (eff 29 oct 25) | I15: =SUM(I7:I14) -> 35711.767 | M15: =B15 -> Billet Cost (eff 29 oct 25) | S15: =SUM(S7:S14) -> 38168.138 | W15: Billet Cost (eff 14th Sep 2023) | AC15: =SUM(AC7:AC14) -> 48012.77
B16: Market price of Billet | I16: 34450 | M16: Market price of Billet | S16: =38050-500 -> 37550 | W16: Market price of Billet | AC16: 46900
B17: Nett Margin | I17: =I16-I15 -> -1261.7673 | M17: Nett Margin | S17: =S16-S15 -> -618.13814 | W17: Nett Margin | AC17: =AC16-AC15 -> -1112.7704
B19: Costing for TMT
B21: Steel Costing | C21: RAIPUR | N21: NCR | X21: NCR
B22: Item | C22: Consumption | D22: Unit | E22: Rate | F22: Cost | M22: Item | N22: Consumption | O22: Unit | P22: Rate | Q22: Cost | W22: Item | X22: Consumption | Y22: Unit | Z22: Rate | AA22: Cost
E23: Rs/Unit
A24: 850 | B24: Pallet DRI | C24: =C7*10/G7 -> 850 | D24: kg | E24: =E7/1000 -> 22.1 | F24: =E24*C24 -> 18785 | M24: Pallet DRI | N24: 480 | O24: kg | P24: =O7/1000 -> 25.2 | Q24: =P24*N24 -> 12096 | W24: Pallet DRI | X24: =W7/AA7*10 -> 63.291139 | Y24: kg | Z24: 32 | AA24: =Z24*X24 -> 2025.3165
A25: 128 | B25: Pig Iron | C25: =C8*10/G8 -> 127.65957 | D25: kg | E25: =E8/1000 -> 31.8 | F25: =E25*C25 -> 4059.5745 | M25: Pig Iron | N25: 130 | O25: kg | P25: =O8/1000 -> 34.9 | Q25: =P25*N25 -> 4537 | W25: Pig Iron | X25: =W8/AA8*10 -> 159.57447 | Y25: kg | Z25: 42.8 | AA25: =Z25*X25 -> 6829.7872
A26: 104 | B26: Scrap | C26: =C9/G9*10 -> 104.16667 | D26: kg | E26: =E9/1000 -> 30.3 | F26: =E26*C26 -> 3156.25 | M26: Scrap | N26: 530 | O26: kg | P26: =O9/1000 -> 29.4 | Q26: =P26*N26 -> 15582 | W26: Scrap | X26: =W9/AA9*10 -> 833.33333 | Y26: kg | Z26: 39.5 | AA26: =Z26*X26 -> 32916.667
B27: Silico Manganese | C27: 14 | D27: kg | E27: =E10 -> 71.7 | F27: =E27*C27 -> 1003.8 | M27: Silico Manganese | N27: 14 | O27: kg | P27: =O10 -> 71.7 | Q27: =P27*N27 -> 1003.8 | W27: Silico Manganese | X27: 14 | Y27: kg | Z27: 69 | AA27: =Z27*X27 -> 966
A28: 119 | B28: Iron Ore DRI | C28: =C11/G11*10 -> 119.04762 | D28: kg | E28: =E11/1000 -> 26.1 | F28: =E28*C28 -> 3107.1429 | M28: Iron Ore DRI | N28: 0 | O28: kg | P28: =O11/1000 -> 29.2 | Q28: =P28*N28 -> 0 | W28: Iron Ore DRI | X28: 0 | Y28: kg | Z28: 34.7 | AA28: =Z28*X28 -> 0
B29: Power | C29: 700 | D29: units | E29: =E12 -> 6.5 | F29: =E29*C29 -> 4550 | M29: Power | N29: 650 | O29: units | P29: =O12 -> 6.5 | Q29: =P29*N29 -> 4225 | W29: Power | X29: 750 | Y29: units | Z29: 6.5 | AA29: =Z29*X29 -> 4875
B30: Stores | C30: 1 | D30: Rs/T | E30: =E13 -> 500 | F30: =E30*C30 -> 500 | M30: Stores | N30: 1 | O30: LS | P30: =O13 -> 500 | Q30: =P30*N30 -> 500 | W30: Stores | X30: 1 | Y30: LS | Z30: 500 | AA30: =Z30*X30 -> 500
B31: Manpower | C31: 1 | D31: Rs/T | E31: =E14 -> 550 | F31: =E31 -> 550 | M31: Manpower | N31: 1 | O31: LS | P31: =O14 -> 550 | Q31: =P31*N31 -> 550 | W31: Manpower | X31: 1 | Y31: LS | Z31: 550 | AA31: =Z31*X31 -> 550
B32: =B15 -> Billet Cost (eff 29 oct 25) | F32: =SUM(F24:F31) -> 35711.767 | M32: =B32 -> Billet Cost (eff 29 oct 25) | Q32: =SUM(Q24:Q31) -> 38493.8 | W32: Billet Cost (eff 14th Sep 2023) | AA32: =SUM(AA24:AA31) -> 48662.77
B33: Market price of Billet | F33: =I16 -> 34450 | M33: Market price of Billet | Q33: 40200 | W33: Market price of Billet | AA33: 46900
B34: Net Margin | F34: =F33-F32 -> -1261.7673 | M34: Net Margin | Q34: =Q33-Q32 -> 1706.2 | W34: Net Margin | AA34: =AA33-AA32 -> -1762.7704
B38: Rolling Mill Cost | C38: Hot charging (own billet - direct rolling ) | G38: Reheating (bought out billets) | M38: Rolling Mill Cost | N38: Hot charging (own billet - direct rolling ) | R38: Reheating (bought out billets) | W38: Rolling Mill Cost | X38: Hot charging (own billet - direct rolling ) | AB38: Reheating (bought out billets)
B40: Item | C40: Consumption | D40: Unit | E40: Rate | F40: Cost | G40: Consumption | H40: Unit | I40: Rate | L40: Cost | M40: Item | N40: Consumption | O40: Unit | P40: Rate | Q40: Cost | R40: Consumption | S40: Unit | T40: Rate | U40: Cost | W40: Item | X40: Consumption | Y40: Unit | Z40: Rate | AA40: Cost | AB40: Consumption | AC40: Unit | AD40: Rate | AE40: Cost
B41: Cost of Billet | F41: =F32 -> 35711.767 | L41: =F32 -> 35711.767 | Q41: =Q33 -> 40200 | U41: =Q33 -> 40200
B42: Scale loss | C42: 0.8 | D42: % | E42: =I15 -> 35711.767 | F42: =E42*C42/100 -> 285.69414 | G42: 1.2 | H42: % | I42: =E42 -> 35711.767 | L42: =I42*G42/100 -> 428.54121 | M42: Scale loss | N42: 0.8 | O42: % | P42: =S15 -> 38168.138 | Q42: =P42*N42/100 -> 305.34511 | R42: 1.2 | S42: % | T42: =P42 -> 38168.138 | U42: =T42*R42/100 -> 458.01766 | W42: Scale loss | X42: 1 | Y42: % | Z42: =AC15 -> 48012.77 | AA42: =Z42*X42/100 -> 480.1277 | AB42: 1.5 | AC42: % | AD42: =Z42 -> 48012.77 | AE42: =AD42*AB42/100 -> 720.19156
B43: Power | C43: 120 | D43: unit | E43: 6.5 | F43: =E43*C43 -> 780 | G43: 120 | H43: unit | I43: 6.5 | L43: =I43*G43 -> 780 | M43: Power | N43: 120 | O43: unit | P43: 6.5 | Q43: =P43*N43 -> 780 | R43: 120 | S43: unit | T43: 6.5 | U43: =T43*R43 -> 780 | W43: Power | X43: 120 | Y43: unit | Z43: 6.5 | AA43: =Z43*X43 -> 780 | AB43: 125 | AC43: unit | AD43: 6.5 | AE43: =AD43*AB43 -> 812.5
B44: Stores | C44: 1 | D44: Rs/T | E44: 400 | F44: =E44*C44 -> 400 | G44: 1 | H44: Rs/T | I44: 400 | L44: =I44*G44 -> 400 | M44: Stores | N44: 1 | O44: Rs/T | P44: 400 | Q44: =P44*N44 -> 400 | R44: 1 | S44: Rs/T | T44: 400 | U44: =T44*R44 -> 400 | W44: Stores | X44: 1 | Y44: Rs/T | Z44: 400 | AA44: =Z44*X44 -> 400 | AB44: 1 | AC44: Rs/T | AD44: 400 | AE44: =AD44*AB44 -> 400
B45: Manpower | C45: 1 | D45: Rs/T | E45: 700 | F45: =E45*C45 -> 700 | G45: 1 | H45: Rs/T | I45: 700 | L45: =I45*G45 -> 700 | M45: Manpower | N45: 1 | O45: Rs/T | P45: 700 | Q45: =P45*N45 -> 700 | R45: 1 | S45: Rs/T | T45: 700 | U45: =T45*R45 -> 700 | W45: Manpower | X45: 1 | Y45: Rs/T | Z45: 700 | AA45: =Z45*X45 -> 700 | AB45: 1 | AC45: Rs/T | AD45: 700 | AE45: =AD45*AB45 -> 700
B46: Fuel cost | C46: 0 | D46: scm/t | E46: 47 | F46: =E46*C46 -> 0 | G46: 40 | H46: scm/t | I46: 47 | L46: =I46*G46 -> 1880 | M46: Fuel cost | N46: 0 | O46: scm/t | P46: 47 | Q46: =P46*N46 -> 0 | R46: 40 | S46: scm/t | T46: 47 | U46: =T46*R46 -> 1880 | W46: Fuel cost | X46: 0 | Y46: scm/t | Z46: 47 | AA46: =Z46*X46 -> 0 | AB46: 40 | AC46: scm/t | AD46: 47 | AE46: =AD46*AB46 -> 1880
B47: Cutting loss | C47: 0 | D47: % | E47: =SUM(F41:F46) -> 37877.461 | F47: =E47*C47/100 -> 0 | G47: 0.5 | H47: % | I47: =SUM(L41:L46) -> 39900.309 | L47: =I47*G47/100 -> 199.50154 | M47: Cutting loss | N47: 0 | O47: % | P47: =SUM(Q41:Q46) -> 42385.345 | Q47: =P47*N47/100 -> 0 | R47: 0.5 | S47: % | T47: =SUM(U41:U46) -> 44418.018 | U47: =T47*R47/100 -> 222.09009 | W47: Cutting loss | X47: 0 | Y47: % | Z47: =Z49+AA49 -> 52639.678 | AA47: =Z47*X47/100 -> 0 | AB47: 1 | AC47: % | AD47: =AD49+AE49+AE44 -> 55289.108 | AE47: =AD47*AB47/100 -> 552.89108
B48: Rolling cost | F48: =SUM(F42:F47) -> 2165.6941 | L48: =SUM(L42:L47) -> 4388.0428 | M48: Rolling cost | Q48: =SUM(Q42:Q47) -> 2185.3451 | U48: =SUM(U42:U47) -> 4440.1077 | W48: Rolling cost | AA48: =SUM(AA42:AA50) -> 1022.6277 | AE48: =SUM(AE42:AE50) -> 3337.6951
B49: Yield loss | C49: 4.5 | D49: % | E49: =SUM(F41:F47) -> 37877.461 | F49: =E49*C49/100 -> 1704.4858 | G49: 4.5 | H49: % | I49: =SUM(L41:L47) -> 40099.81 | L49: =I49*G49/100 -> 1804.4915 | M49: Yield loss | N49: 4.5 | O49: % | P49: =SUM(Q41:Q47) -> 42385.345 | Q49: =P49*N49/100 -> 1907.3405 | R49: 4.5 | S49: % | T49: =SUM(U41:U47) -> 44640.108 | U49: =T49*R49/100 -> 2008.8048 | W49: Yield loss | X49: 4.5 | Y49: % | Z49: =Z42+AA42+AA43+AA44+AA45+AA46 -> 50372.898 | AA49: =Z49*X49/100 -> 2266.7804 | AB49: 4.5 | AC49: % | AD49: =AD42+AE42+AE43+AE44+AE45+AE46 -> 52525.462 | AE49: =AD49*AB49/100 -> 2363.6458
...

Sheet Sheet1

Sheet DGP
B2: Costing for TMT
B4: Steel Costing | C4: Durgapur
B5: Item | C5: Consumption | D5: Unit | E5: Rate | F5: Cost | G5: Recovery amount | H5: Effective cost | I5: Total cost | K5: Delta with Raipur
K6: Rate | L6: Cost | M6: Recovery amount | N6: Effective cost | O6: Total cost
A7: 850 | B7: Pallet DRI | C7: 68 | D7: % | E7: 25600 | F7: =E7*C7/100 -> 17408 | G7: 0.8 | H7: =F7/G7 -> 21760 | I7: =H7 -> 21760 | K7: =E7-Raipur!E7 -> -1050 | L7: =F7-Raipur!F7 -> -714 | M7: =G7-Raipur!G7 -> 0 | N7: =H7-Raipur!H7 -> -892.5 | O7: =I7-Raipur!I7 -> -892.5
A8: 128 | B8: Pig Iron | C8: 12 | D8: % | E8: 37650 | F8: =E8*C8/100 -> 4518 | G8: 0.94 | H8: =F8/G8 -> 4806.383 | I8: =H8 -> 4806.383 | K8: =E8-Raipur!E8 -> 100 | L8: =F8-Raipur!F8 -> 12 | M8: =G8-Raipur!G8 -> 0 | N8: =H8-Raipur!H8 -> 12.765957 | O8: =I8-Raipur!I8 -> 12.765957
A9: 104 | B9: Scrap | C9: 10 | D9: % | E9: 33500 | F9: =E9*C9/100 -> 3350 | G9: 0.96 | H9: =F9/G9 -> 3489.5833 | I9: =H9 -> 3489.5833 | K9: =E9-Raipur!E9 -> -1300 | L9: =F9-Raipur!F9 -> -130 | M9: =G9-Raipur!G9 -> 0 | N9: =H9-Raipur!H9 -> -135.41667 | O9: =I9-Raipur!I9 -> -135.41667
B10: Silico Manganese | C10: 14 | D10: kg | E10: =Raipur!E10 -> 74.4 | F10: =E10*C10 -> 1041.6 | G10: 1 | H10: =F10/G10 -> 1041.6 | I10: =H10 -> 1041.6 | K10: =E10-Raipur!E10 -> 0 | L10: =F10-Raipur!F10 -> 0 | M10: =G10-Raipur!G10 -> 0 | N10: =H10-Raipur!H10 -> 0 | O10: =I10-Raipur!I10 -> 0
A11: 119 | B11: Iron Ore DRI | C11: 10 | D11: % | E11: 27700 | F11: =E11*C11/100 -> 2770 | G11: 0.84 | H11: =F11/G11 -> 3297.619 | I11: =H11 -> 3297.619 | K11: =E11-Raipur!E11 -> -2800 | L11: =F11-Raipur!F11 -> -280 | M11: =G11-Raipur!G11 -> 0 | N11: =H11-Raipur!H11 -> -333.33333 | O11: =I11-Raipur!I11 -> -333.33333
B12: Power (incldg ancilliaries) | C12: 700 | E12: 6.5 | F12: =E12*C12 -> 4550 | I12: =E12*C12 -> 4550 | K12: =E12-Raipur!E12 -> 0 | L12: =F12-Raipur!F12 -> 0 | M12: =G12-Raipur!G12 -> 0 | N12: =H12-Raipur!H12 -> 0 | O12: =I12-Raipur!I12 -> 0
B13: Stores | C13: 1 | D13: Rs/T | E13: 500 | F13: =E13*C13 -> 500 | I13: 550 | K13: =E13-Raipur!E13 -> 0 | L13: =F13-Raipur!F13 -> 0 | M13: =G13-Raipur!G13 -> 0 | N13: =H13-Raipur!H13 -> 0 | O13: =I13-Raipur!I13 -> 0
B14: Manpower | C14: 1 | D14: Rs/T | E14: 550 | F14: =E14 -> 550 | I14: 500 | K14: =E14-Raipur!E14 -> 0 | L14: =F14-Raipur!F14 -> 0 | M14: =G14-Raipur!G14 -> 0 | N14: =H14-Raipur!H14 -> 0 | O14: =I14-Raipur!I14 -> 0
B15: =Raipur!B15 -> Billet Cost | I15: =SUM(I7:I14) -> 39995.185 | O15: =SUM(O7:O14) -> -1348.484
B16: Market price of Billet | I16: 41200
B17: Nett Margin | I17: =I16-I15 -> 1204.8146
B19: Costing for TMT
B21: Steel Costing | C21: Durgapur
B22: Item | C22: Consumption | D22: Unit | E22: Rate | F22: Cost
E23: Rs/Unit
A24: 850 | B24: Pallet DRI | C24: =C7*10/G7 -> 850 | D24: kg | E24: =E7/1000 -> 25.6 | F24: =E24*C24 -> 21760
A25: 128 | B25: Pig Iron | C25: =C8*10/G8 -> 127.65957 | D25: kg | E25: =E8/1000 -> 37.65 | F25: =E25*C25 -> 4806.383
A26: 104 | B26: Scrap | C26: =C9/G9*10 -> 104.16667 | D26: kg | E26: =E9/1000 -> 33.5 | F26: =E26*C26 -> 3489.5833
B27: Silico Manganese | C27: 14 | D27: kg | E27: =E10 -> 74.4 | F27: =E27*C27 -> 1041.6
A28: 119 | B28: Iron Ore DRI | C28: =C11/G11*10 -> 119.04762 | D28: kg | E28: =E11/1000 -> 27.7 | F28: =E28*C28 -> 3297.619
B29: Power | C29: 700 | D29: units | E29: =E12 -> 6.5 | F29: =E29*C29 -> 4550
B30: Stores | C30: 1 | D30: Rs/T | E30: =E13 -> 500 | F30: =E30*C30 -> 500
B31: Manpower | C31: 1 | D31: Rs/T | E31: =E14 -> 550 | F31: =E31 -> 550
B32: =B15 -> Billet Cost | F32: =SUM(F24:F31) -> 39995.185
B33: Market price of Billet | F33: =I16 -> 41200
B34: Net Margin | F34: =F33-F32 -> 1204.8146
B38: Rolling Mill Cost | C38: Hot charging (own billet - direct rolling ) | G38: Reheating (bought out billets)
B40: Item | C40: Consumption | D40: Unit | E40: Rate | F40: Cost | G40: Consumption | H40: Unit | I40: Rate | J40: Cost | O40: Total cost
B41: Cost of Billet | F41: =F32 -> 39995.185 | J41: =F32 -> 39995.185 | O41: =F41-Raipur!F21 -> -1348.484
B42: Scale loss | C42: 0.8 | D42: % | E42: =I15 -> 39995.185 | F42: =E42*C42/100 -> 319.96148 | G42: 1.2 | H42: % | I42: =E42 -> 39995.185 | J42: =I42*G42/100 -> 479.94222 | O42: =F42-Raipur!F22 -> -10.787872
B43: Power | C43: 120 | D43: unit | E43: 6.5 | F43: =E43*C43 -> 780 | G43: 120 | H43: unit | I43: 6.5 | J43: =I43*G43 -> 780 | O43: =F43-Raipur!F23 -> 0
B44: Stores | C44: 1 | D44: Rs/T | E44: 400 | F44: =E44*C44 -> 400 | G44: 1 | H44: Rs/T | I44: 400 | J44: =I44*G44 -> 400 | O44: =F44-Raipur!F24 -> 0
B45: Manpower | C45: 1 | D45: Rs/T | E45: 700 | F45: =E45*C45 -> 700 | G45: 1 | H45: Rs/T | I45: 700 | J45: =I45*G45 -> 700 | O45: =F45-Raipur!F25 -> 0
B46: Fuel cost | C46: 0 | D46: scm/t | E46: 47 | F46: =E46*C46 -> 0 | G46: 40 | H46: scm/t | I46: 47 | J46: =I46*G46 -> 1880 | O46: =F46-Raipur!F26 -> 0
B47: Cutting loss | C47: 0 | D47: % | E47: =SUM(F41:F46) -> 42195.147 | F47: =E47*C47/100 -> 0 | G47: 0.5 | H47: % | I47: =SUM(J41:J46) -> 44235.128 | J47: =I47*G47/100 -> 221.17564 | O47: =F47-Raipur!F27 -> 0
B48: Rolling cost | F48: =SUM(F42:F47) -> 2199.9615 | J48: =SUM(J42:J47) -> 4461.1179 | O48: =F48-Raipur!F28 -> -10.787872
...

Sheet Sheet2

Sheet Steel Mint Inputs
D1: =68/0.8 -> 85
B2: Costing for TMT
B4: Steel Costing | C4: RAIPUR | K4: NCR | U4: NCR Fe550
B5: Item | C5: Consumption | D5: Unit | E5: Rate | F5: Cost | G5: Recovery amount | H5: Effective cost | I5: Total cost | K5: Consumption | L5: Unit | M5: Rate | N5: Cost | O5: Recovery amount | P5: Effective cost | Q5: Total cost | U5: Consumption | V5: Unit | W5: Rate | X5: Cost | Y5: Recovery amount | Z5: Effective cost | AA5: Total cost
J6: Ton
A7: 850 | B7: Pallet DRI | C7: 68 | D7: % | E7: 24400 | F7: =E7*C7/100 -> 16592 | G7: 0.8 | H7: =F7/G7 -> 20740 | I7: =H7 -> 20740 | J7: =0.68*0.79 -> 0.5372 | K7: 38 | L7: % | M7: =E7+3000 -> 27400 | N7: =M7*K7/100 -> 10412 | O7: 0.79 | P7: =N7/O7 -> 13179.747 | Q7: =P7 -> 13179.747 | U7: 5 | V7: % | W7: 27.4 | X7: =W7*U7/100 -> 1.37 | Y7: 0.79 | Z7: =X7/Y7 -> 1.7341772 | AA7: =Z7 -> 1.7341772
A8: 128 | B8: Pig Iron | C8: 0 | D8: % | E8: 38000 | F8: =E8*C8/100 -> 0 | G8: 0.94 | H8: =F8/G8 -> 0 | I8: =H8 -> 0 | J8: =0.12*0.955 -> 0.1146 | K8: 0 | L8: % | M8: =E8+3000 -> 41000 | N8: =M8*K8/100 -> 0 | O8: 0.94 | P8: =N8/O8 -> 0 | Q8: =P8 -> 0 | U8: 15 | V8: % | W8: 39000 | X8: =W8*U8/100 -> 5850 | Y8: 0.94 | Z8: =X8/Y8 -> 6223.4043 | AA8: =Z8 -> 6223.4043
A9: 104 | B9: Scrap | C9: 10 | D9: % | E9: 37250 | F9: =E9*C9/100 -> 3725 | G9: 0.96 | H9: =F9/G9 -> 3880.2083 | I9: =H9 -> 3880.2083 | J9: =0.1*0.96 -> 0.096 | K9: 50 | L9: % | M9: 37250 | N9: =M9*K9/100 -> 18625 | O9: 0.96 | P9: =N9/O9 -> 19401.042 | Q9: =P9 -> 19401.042 | U9: 80 | V9: % | W9: 37250 | X9: =W9*U9/100 -> 29800 | Y9: 0.96 | Z9: =X9/Y9 -> 31041.667 | AA9: =Z9 -> 31041.667
B10: Silico Manganese | C10: 12 | D10: kg | E10: 71.8 | F10: =E10*C10 -> 861.6 | G10: 1 | H10: =F10/G10 -> 861.6 | I10: =H10 -> 861.6 | J10: 0.014 | K10: 12 | L10: kg | M10: 72 | N10: =M10*K10 -> 864 | O10: 1 | P10: =N10/O10 -> 864 | Q10: =P10 -> 864 | U10: 12 | V10: kg | W10: 72 | X10: =W10*U10 -> 864 | Y10: 1 | Z10: =X10/Y10 -> 864 | AA10: =Z10 -> 864
A11: 119 | B11: Iron Ore DRI | C11: 22 | D11: % | E11: 25400 | F11: =E11*C11/100 -> 5588 | G11: 0.84 | H11: =F11/G11 -> 6652.381 | I11: =H11 -> 6652.381 | J11: =0.1*0.83 -> 0.083 | K11: 12 | L11: % | M11: =E11+3000 -> 28400 | N11: =M11*K11/100 -> 3408 | O11: 0.83 | P11: =N11/O11 -> 4106.0241 | Q11: =P11 -> 4106.0241 | U11: 0 | V11: % | W11: 28400 | X11: =W11*U11/100 -> 0 | Y11: 0.83 | Z11: =X11/Y11 -> 0 | AA11: =Z11 -> 0
B12: Power (incldg ancilliaries) | C12: 700 | E12: 6.8 | F12: =E12*C12 -> 4760 | I12: =E12*C12 -> 4760 | K12: 650 | M12: 6.5 | N12: =M12*K12 -> 4225 | Q12: =M12*K12 -> 4225 | U12: 650 | W12: 6.5 | X12: =W12*U12 -> 4225 | AA12: =W12*U12 -> 4225
B13: Stores | C13: 1 | D13: Rs/T | E13: 500 | F13: =E13*C13 -> 500 | I13: 550 | K13: 1 | L13: LS | M13: 500 | N13: =M13*K13 -> 500 | Q13: =M13*K13 -> 500 | U13: 1 | V13: LS | W13: 500 | X13: =W13*U13 -> 500 | AA13: =W13*U13 -> 500
B14: Manpower | C14: 1 | D14: Rs/T | E14: 550 | F14: =E14 -> 550 | I14: 500 | K14: 1 | L14: LS | M14: 550 | N14: =M14 -> 550 | Q14: =M14*K14 -> 550 | U14: 1 | V14: LS | W14: 550 | X14: =W14 -> 550 | AA14: =W14*U14 -> 550
B15: Billet Cost (eff 14th Sep 2023) | I15: =SUM(I7:I14) -> 37944.189 | K15: Billet Cost (eff 14th Sep 2023) | Q15: =SUM(Q7:Q14) -> 42825.813 | U15: Billet Cost (eff 14th Sep 2023) | AA15: =SUM(AA7:AA14) -> 43405.805
B16: Market price of Billet | I16: 44300 | K16: Market price of Billet | Q16: 46900 | U16: Market price of Billet | AA16: 46900
B17: Net Margin | I17: =I16-I15 -> 6355.8107 | K17: Net Margin | Q17: =Q16-Q15 -> 4074.1874 | U17: Net Margin | AA17: =AA16-AA15 -> 3494.1949
B19: Costing for TMT
B21: Steel Costing | C21: RAIPUR | L21: NCR | V21: NCR
B22: Item | C22: Consumption | D22: Unit | E22: Rate (Rs./unit) | F22: Cost | K22: Item | L22: Consumption | M22: Unit | N22: Rate | O22: Cost | U22: Item | V22: Consumption | W22: Unit | X22: Rate | Y22: Cost
G23: Ton
A24: 850 | B24: Pallet DRI | C24: 858.23 | D24: kg | E24: 25.25 | F24: =E24*C24 -> 21670.307 | G24: =0.68*0.79 -> 0.5372 | H24: =C24*0.79 -> 678.0017 | K24: Pallet DRI | L24: =K7/O7*10 -> 481.01266 | M24: kg | N24: 27.4 | O24: =N24*L24 -> 13179.747 | U24: Pallet DRI | V24: =U7/Y7*10 -> 63.291139 | W24: kg | X24: 27.4 | Y24: =X24*V24 -> 1734.1772
A25: 128 | B25: Pig Iron | C25: =C8*10/G8 -> 0 | D25: kg | E25: 37.85 | F25: =E25*C25 -> 0 | G25: =0.12*0.955 -> 0.1146 | K25: Pig Iron | L25: 0 | M25: kg | N25: 39.5 | O25: =N25*L25 -> 0 | U25: Pig Iron | V25: =U8/Y8*10 -> 159.57447 | W25: kg | X25: 39 | Y25: =X25*V25 -> 6223.4043
A26: 104 | B26: Scrap | C26: 93.75 | D26: kg | E26: 36.8 | F26: =E26*C26 -> 3450 | G26: =0.1*0.96 -> 0.096 | H26: =C26*0.96 -> 90 | K26: Scrap | L26: =K9/O9*10 -> 520.83333 | M26: kg | N26: 36.8 | O26: =N26*L26 -> 19166.667 | U26: Scrap | V26: =U9/Y9*10 -> 833.33333 | W26: kg | X26: 37.25 | Y26: =X26*V26 -> 31041.667
B27: Silico Manganese | C27: 12 | D27: kg | E27: 69.3 | F27: =E27*C27 -> 831.6 | G27: 0.014 | H27: 12 | K27: Silico Manganese | L27: 12 | M27: kg | N27: 72.3 | O27: =N27*L27 -> 867.6 | U27: Silico Manganese | V27: 12 | W27: kg | X27: 72 | Y27: =X27*V27 -> 864
A28: 119 | B28: Iron Ore DRI | C28: 265.06 | D28: kg | E28: 29.35 | F28: =E28*C28 -> 7779.511 | G28: =0.1*0.83 -> 0.083 | H28: =C28*0.83 -> 219.9998 | K28: Iron Ore DRI | L28: =K11/O11*10 -> 144.57831 | M28: kg | N28: 29.5 | O28: =N28*L28 -> 4265.0602 | U28: Iron Ore DRI | V28: 0 | W28: kg | X28: 28.4 | Y28: =X28*V28 -> 0
B29: Power | C29: 750 | D29: units | E29: 6.5 | F29: =E29*C29 -> 4875 | K29: Power | L29: 700 | M29: units | N29: 6.5 | O29: =N29*L29 -> 4550 | U29: Power | V29: 700 | W29: units | X29: 6.5 | Y29: =X29*V29 -> 4550
B30: Stores | C30: 1 | D30: Rs/T | E30: 550 | F30: =E30*C30 -> 550 | K30: Stores | L30: 1 | M30: LS | N30: 550 | O30: =N30*L30 -> 550 | U30: Stores | V30: 1 | W30: LS | X30: 500 | Y30: =X30*V30 -> 500
B31: Manpower | C31: 1 | D31: Rs/T | E31: 500 | F31: =E31 -> 500 | K31: Manpower | L31: 1 | M31: LS | N31: 500 | O31: =N31*L31 -> 500 | U31: Manpower | V31: 1 | W31: LS | X31: 550 | Y31: =X31*V31 -> 550
B32: Billet Cost (eff. 15th Sep 2023) | F32: =SUM(F24:F31) -> 39656.418 | K32: Billet Cost (eff 15th Sep 2023) | O32: =SUM(O24:O31) -> 43079.074 | U32: Billet Cost (eff 14th Sep 2023) | Y32: =SUM(Y24:Y31) -> 45463.248
B33: Market price of Billet | F33: 39250 | K33: Market price of Billet | O33: 42300 | U33: Market price of Billet | Y33: 43800
B34: Net Margin | F34: =F33-F32 -> -406.4185 | K34: Net Margin | O34: =O33-O32 -> -779.07374 | U34: Net Margin | Y34: =Y33-Y32 -> -1663.2481
B37: RAIPUR COMPARISON | K37: NCR COMPARISON | U37: NCR COMPARISON
B38: Rolling Mill Cost | C38: Hot charging (own billet - direct rolling) | G38: Reheating (bought out billets) | K38: Rolling Mill Cost | L38: Hot charging (own billet - direct rolling) | P38: Reheating (bought out billets) | U38: Rolling Mill Cost | V38: Hot charging (own billet - direct rolling ) | Z38: Reheating (bought out billets)
B40: Item | C40: Consumption | D40: Unit | E40: Rate | F40: Cost | G40: Consumption | H40: Unit | I40: Rate | J40: Cost | K40: Item | L40: Consumption | M40: Unit | N40: Rate | O40: Cost | P40: Consumption | Q40: Unit | R40: Rate | S40: Cost | U40: Item | V40: Consumption | W40: Unit | X40: Rate | Y40: Cost | Z40: Consumption | AA40: Unit | AB40: Rate | AC40: Cost
B41: Cost of Billet (Market Price) | F41: =F32 -> 39656.418 | J41: =F32 -> 39656.418 | O41: =O33 -> 42300 | S41: =O33 -> 42300
B42: Scale loss | C42: 0.8 | D42: % | E42: =I15 -> 37944.189 | F42: =E42*C42/100 -> 303.55351 | G42: 1.2 | H42: % | I42: =E42 -> 37944.189 | J42: =I42*G42/100 -> 455.33027 | K42: Scale loss | L42: 0.8 | M42: % | N42: =Q15 -> 42825.813 | O42: =N42*L42/100 -> 342.6065 | P42: 1.2 | Q42: % | R42: =N42 -> 42825.813 | S42: =R42*P42/100 -> 513.90975 | U42: Scale loss | V42: 1 | W42: % | X42: =AA15 -> 43405.805 | Y42: =X42*V42/100 -> 434.05805 | Z42: 1.5 | AA42: % | AB42: =X42 -> 43405.805 | AC42: =AB42*Z42/100 -> 651.08708
B43: Power | C43: 110 | D43: unit | E43: 6.5 | F43: =E43*C43 -> 715 | G43: 110 | H43: unit | I43: 6.5 | J43: =I43*G43 -> 715 | K43: Power | L43: 110 | M43: unit | N43: 6.5 | O43: =N43*L43 -> 715 | P43: 110 | Q43: unit | R43: 6.5 | S43: =R43*P43 -> 715 | U43: Power | V43: 120 | W43: unit | X43: 6.5 | Y43: =X43*V43 -> 780 | Z43: 125 | AA43: unit | AB43: 6.5 | AC43: =AB43*Z43 -> 812.5
B44: Stores | C44: 1 | D44: Rs/T | E44: 400 | F44: =E44*C44 -> 400 | G44: 1 | H44: Rs/T | I44: 400 | J44: =I44*G44 -> 400 | K44: Stores | L44: 1 | M44: Rs/T | N44: 400 | O44: =N44*L44 -> 400 | P44: 1 | Q44: Rs/T | R44: 400 | S44: =R44*P44 -> 400 | U44: Stores | V44: 1 | W44: Rs/T | X44: 400 | Y44: =X44*V44 -> 400 | Z44: 1 | AA44: Rs/T | AB44: 400 | AC44: =AB44*Z44 -> 400
B45: Manpower | C45: 1 | D45: Rs/T | E45: 800 | F45: =E45*C45 -> 800 | G45: 1 | H45: Rs/T | I45: 800 | J45: =I45*G45 -> 800 | K45: Manpower | L45: 1 | M45: Rs/T | N45: 700 | O45: =N45*L45 -> 700 | P45: 1 | Q45: Rs/T | R45: 700 | S45: =R45*P45 -> 700 | U45: Manpower | V45: 1 | W45: Rs/T | X45: 700 | Y45: =X45*V45 -> 700 | Z45: 1 | AA45: Rs/T | AB45: 700 | AC45: =AB45*Z45 -> 700
B46: Fuel cost / Coal | C46: 0 | D46: scm/t | E46: 47 | F46: =E46*C46 -> 0 | G46: 100 | H46: kg | I46: 8.31 | J46: =I46*G46 -> 831 | K46: Fuel cost / Coal | L46: 0 | M46: scm/t | N46: 47 | O46: =N46*L46 -> 0 | P46: 100 | Q46: kg | R46: 8.31 | S46: =R46*P46 -> 831 | U46: Fuel cost | V46: 0 | W46: scm/t | X46: 47 | Y46: =X46*V46 -> 0 | Z46: 100 | AA46: kg | AB46: 8 | AC46: =AB46*Z46 -> 800
...
